<?xml version="1.0" encoding="utf-8" ?>
<!-- This URDF was automatically created by SolidWorks to URDF Exporter! Originally created by Stephen Brawner (brawner@gmail.com) 
     Commit Version: 1.6.0-1-g15f4949  Build Version: 1.6.7594.29634
     For more information, please see http://wiki.ros.org/sw_urdf_exporter -->
<robot name="garbage_quick_sort_robot">
    <link name="base_link">
        <inertial>
            <origin xyz="-5.31932292919015E-19 0 0.025" rpy="0 0 0" />
            <mass value="0.015707963267949" />
            <inertia ixx="3.66519142918809E-06" ixy="0" ixz="4.89658094079248E-39" iyy="3.66519142918809E-06" iyz="-7.588784500269E-39" izz="7.85398163397449E-07" />
        </inertial>
        <visual>
            <origin xyz="0 0 0" rpy="0 0 0" />
            <geometry>
                <mesh filename="package://garbage_quick_sort_robot/meshes/base_link.STL" />
            </geometry>
            <material name="">
                <color rgba="0.792156862745098 0.819607843137255 0.933333333333333 1" />
            </material>
        </visual>
        <collision>
            <origin xyz="0 0 0" rpy="0 0 0" />
            <geometry>
                <mesh filename="package://garbage_quick_sort_robot/meshes/base_link.STL" />
            </geometry>
        </collision>
    </link>
    <link name="link_1">
        <inertial>
            <origin xyz="2.76803785256884E-19 1.37466054338567E-17 0.0452098847240084" rpy="0 0 0" />
            <mass value="0.0985454479856908" />
            <inertia ixx="0.000173459349756366" ixy="-6.14254163131044E-22" ixz="3.71333229999255E-21" iyy="0.000138730938371706" iyz="2.47619162015144E-21" izz="5.10302508014298E-05" />
        </inertial>
        <visual>
            <origin xyz="0 0 0" rpy="0 0 0" />
            <geometry>
                <mesh filename="package://garbage_quick_sort_robot/meshes/link_1.STL" />
            </geometry>
            <material name="">
                <color rgba="0.792156862745098 0.819607843137255 0.933333333333333 1" />
            </material>
        </visual>
        <collision>
            <origin xyz="0 0 0" rpy="0 0 0" />
            <geometry>
                <mesh filename="package://garbage_quick_sort_robot/meshes/link_1.STL" />
            </geometry>
        </collision>
    </link>
    <joint name="joint_1" type="continuous">
        <origin xyz="0 0 0" rpy="0 0 0" />
        <parent link="base_link" />
        <child link="link_1" />
        <axis xyz="0 0 1" />
    </joint>
    <link name="link_2">
        <inertial>
            <origin xyz="0.0933356518856813 8.19889789753123E-06 -1.49708834648599E-06" rpy="0 0 0" />
            <mass value="0.0483487129594158" />
            <inertia ixx="3.67282206632682E-06" ixy="5.59056640138914E-09" ixz="6.70725815697787E-09" iyy="0.000176109264034434" iyz="3.5597692325225E-11" izz="0.000172564836827597" />
        </inertial>
        <visual>
            <origin xyz="0 0 0" rpy="0 0 0" />
            <geometry>
                <mesh filename="package://garbage_quick_sort_robot/meshes/link_2.STL" />
            </geometry>
            <material name="">
                <color rgba="0.752941176470588 0.752941176470588 0.752941176470588 1" />
            </material>
        </visual>
        <collision>
            <origin xyz="0 0 0" rpy="0 0 0" />
            <geometry>
                <mesh filename="package://garbage_quick_sort_robot/meshes/link_2.STL" />
            </geometry>
        </collision>
    </link>
    <joint name="joint_2" type="continuous">
        <origin xyz="0 0 0.131" rpy="0 0 0" />
        <parent link="link_1" />
        <child link="link_2" />
        <axis xyz="0 -1 0" />
    </joint>
    <link name="link_3">
        <inertial>
            <origin xyz="0.093444934538762 -1.05962001749503E-05 2.80655551698761E-06" rpy="0 0 0" />
            <mass value="0.0605358880934335" />
            <inertia ixx="4.65997625475644E-06" ixy="-1.44061712601069E-08" ixz="-1.24839961746318E-09" iyy="0.000220424607385293" iyz="-2.56646262184566E-10" izz="0.000216016422770127" />
        </inertial>
        <visual>
            <origin xyz="0 0 0" rpy="0 0 0" />
            <geometry>
                <mesh filename="package://garbage_quick_sort_robot/meshes/link_3.STL" />
            </geometry>
            <material name="">
                <color rgba="0.752941176470588 0.752941176470588 0.752941176470588 1" />
            </material>
        </visual>
        <collision>
            <origin xyz="0 0 0" rpy="0 0 0" />
            <geometry>
                <mesh filename="package://garbage_quick_sort_robot/meshes/link_3.STL" />
            </geometry>
        </collision>
    </link>
    <joint name="joint_3" type="continuous">
        <origin xyz="0.186 0 0" rpy="0 0 0" />
        <parent link="link_2" />
        <child link="link_3" />
        <axis xyz="0 -1 0" />
    </joint>
    <link name="link_4">
        <inertial>
            <origin xyz="0.0808689542406464 -6.94903621645494E-06 0" rpy="0 0 0" />
            <mass value="0.0426411677610806" />
            <inertia ixx="3.21639882309365E-06" ixy="-8.43140562221866E-09" ixz="-1.0027185306975E-20" iyy="0.000119543292909613" iyz="-1.73207698133633E-23" izz="0.000116440599749008" />
        </inertial>
        <visual>
            <origin xyz="0 0 0" rpy="0 0 0" />
            <geometry>
                <mesh filename="package://garbage_quick_sort_robot/meshes/link_4.STL" />
            </geometry>
            <material name="">
                <color rgba="0.752941176470588 0.752941176470588 0.752941176470588 1" />
            </material>
        </visual>
        <collision>
            <origin xyz="0 0 0" rpy="0 0 0" />
            <geometry>
                <mesh filename="package://garbage_quick_sort_robot/meshes/link_4.STL" />
            </geometry>
        </collision>
    </link>
    <joint name="joint_4" type="continuous">
        <origin xyz="0.186 0 0" rpy="0 0 0" />
        <parent link="link_3" />
        <child link="link_4" />
        <axis xyz="0 -1 0" />
    </joint>
    <transmission name="trans_joint_1">
        <type>transmission_interface/SimpleTransmission</type>
        <joint name="joint_1">
            <hardwareInterface>hardware_interface/EffortJointInterface</hardwareInterface>
        </joint>
        <actuator name="joint_1_motor">
            <hardwareInterface>hardware_interface/EffortJointInterface</hardwareInterface>
            <mechanicalReduction>1</mechanicalReduction>
        </actuator>
    </transmission>
    <transmission name="trans_joint_2">
        <type>transmission_interface/SimpleTransmission</type>
        <joint name="joint_2">
            <hardwareInterface>hardware_interface/EffortJointInterface</hardwareInterface>
        </joint>
        <actuator name="joint_2_motor">
            <hardwareInterface>hardware_interface/EffortJointInterface</hardwareInterface>
            <mechanicalReduction>1</mechanicalReduction>
        </actuator>
    </transmission>
    <transmission name="trans_joint_3">
        <type>transmission_interface/SimpleTransmission</type>
        <joint name="joint_3">
            <hardwareInterface>hardware_interface/EffortJointInterface</hardwareInterface>
        </joint>
        <actuator name="joint_3_motor">
            <hardwareInterface>hardware_interface/EffortJointInterface</hardwareInterface>
            <mechanicalReduction>1</mechanicalReduction>
        </actuator>
    </transmission>
    <transmission name="trans_joint_4">
        <type>transmission_interface/SimpleTransmission</type>
        <joint name="joint_4">
            <hardwareInterface>hardware_interface/EffortJointInterface</hardwareInterface>
        </joint>
        <actuator name="joint_4_motor">
            <hardwareInterface>hardware_interface/EffortJointInterface</hardwareInterface>
            <mechanicalReduction>1</mechanicalReduction>
        </actuator>
    </transmission>
    <gazebo>
        <plugin name="gazebo_ros_control">
            <robotNamespace>/</robotNamespace>
        </plugin>
    </gazebo>
</robot>

