<?xml version="1.0" encoding="utf-8"?>
<!-- This URDF was automatically created by SolidWorks to URDF Exporter! Originally created by Stephen Brawner (brawner@gmail.com) 
     Commit Version: 1.6.0-1-g15f4949  Build Version: 1.6.7594.29634
     For more information, please see http://wiki.ros.org/sw_urdf_exporter -->
<robot
  name="garbage_quick_sort_robot">
  <link
    name="base_link">
    <inertial>
      <origin
        xyz="-5.3193E-19 0 0.025"
        rpy="0 0 0" />
      <mass
        value="0.015708" />
      <inertia
        ixx="3.6652E-06"
        ixy="0"
        ixz="4.8966E-39"
        iyy="3.6652E-06"
        iyz="-7.5888E-39"
        izz="7.854E-07" />
    </inertial>
    <visual>
      <origin
        xyz="0 0 0"
        rpy="0 0 0" />
      <geometry>
        <mesh
          filename="package://garbage_quick_sort_robot/meshes/base_link.STL" />
      </geometry>
      <material
        name="">
        <color
          rgba="0.79216 0.81961 0.93333 1" />
      </material>
    </visual>
    <collision>
      <origin
        xyz="0 0 0"
        rpy="0 0 0" />
      <geometry>
        <mesh
          filename="package://garbage_quick_sort_robot/meshes/base_link.STL" />
      </geometry>
    </collision>
  </link>
  <link
    name="link_1">
    <inertial>
      <origin
        xyz="2.6841E-18 1.1915E-17 0.045321"
        rpy="0 0 0" />
      <mass
        value="0.098659" />
      <inertia
        ixx="0.00017459"
        ixy="2.4703E-22"
        ixz="-6.3468E-21"
        iyy="0.00013979"
        iyz="-4.8845E-21"
        izz="5.1119E-05" />
    </inertial>
    <visual>
      <origin
        xyz="0 0 0"
        rpy="0 0 0" />
      <geometry>
        <mesh
          filename="package://garbage_quick_sort_robot/meshes/link_1.STL" />
      </geometry>
      <material
        name="">
        <color
          rgba="0.79216 0.81961 0.93333 1" />
      </material>
    </visual>
    <collision>
      <origin
        xyz="0 0 0"
        rpy="0 0 0" />
      <geometry>
        <mesh
          filename="package://garbage_quick_sort_robot/meshes/link_1.STL" />
      </geometry>
    </collision>
  </link>
  <joint
    name="joint_1"
    type="continuous">
    <origin
      xyz="0 0 0"
      rpy="0 0 0" />
    <parent
      link="base_link" />
    <child
      link="link_1" />
    <axis
      xyz="0 0 1" />
  </joint>
  <link
    name="link_2">
    <inertial>
      <origin
        xyz="0.11804 6.5686E-06 -1.1994E-06"
        rpy="0 0 0" />
      <mass
        value="0.060349" />
      <inertia
        ixx="4.5888E-06"
        ixy="-8.3895E-11"
        ixz="8.5385E-09"
        iyy="0.00033599"
        iyz="3.5716E-11"
        izz="0.00033156" />
    </inertial>
    <visual>
      <origin
        xyz="0 0 0"
        rpy="0 0 0" />
      <geometry>
        <mesh
          filename="package://garbage_quick_sort_robot/meshes/link_2.STL" />
      </geometry>
      <material
        name="">
        <color
          rgba="0.75294 0.75294 0.75294 1" />
      </material>
    </visual>
    <collision>
      <origin
        xyz="0 0 0"
        rpy="0 0 0" />
      <geometry>
        <mesh
          filename="package://garbage_quick_sort_robot/meshes/link_2.STL" />
      </geometry>
    </collision>
  </link>
  <joint
    name="joint_2"
    type="continuous">
    <origin
      xyz="0 0 0.13138"
      rpy="0 0 0" />
    <parent
      link="link_1" />
    <child
      link="link_2" />
    <axis
      xyz="0 -1 0" />
  </joint>
  <link
    name="link_3">
    <inertial>
      <origin
        xyz="0.093445 -1.0596E-05 2.8066E-06"
        rpy="0 0 0" />
      <mass
        value="0.060536" />
      <inertia
        ixx="4.66E-06"
        ixy="-1.4406E-08"
        ixz="-1.2484E-09"
        iyy="0.00022042"
        iyz="-2.5665E-10"
        izz="0.00021602" />
    </inertial>
    <visual>
      <origin
        xyz="0 0 0"
        rpy="0 0 0" />
      <geometry>
        <mesh
          filename="package://garbage_quick_sort_robot/meshes/link_3.STL" />
      </geometry>
      <material
        name="">
        <color
          rgba="0.75294 0.75294 0.75294 1" />
      </material>
    </visual>
    <collision>
      <origin
        xyz="0 0 0"
        rpy="0 0 0" />
      <geometry>
        <mesh
          filename="package://garbage_quick_sort_robot/meshes/link_3.STL" />
      </geometry>
    </collision>
  </link>
  <joint
    name="joint_3"
    type="continuous">
    <origin
      xyz="0.236 0 0"
      rpy="0 0 0" />
    <parent
      link="link_2" />
    <child
      link="link_3" />
    <axis
      xyz="0 -1 0" />
  </joint>
  <link
    name="link_4">
    <inertial>
      <origin
        xyz="0.051118 -1.0404E-05 1.1102E-16"
        rpy="0 0 0" />
      <mass
        value="0.028481" />
      <inertia
        ixx="2.1355E-06"
        ixy="-3.3969E-09"
        ixz="-4.1231E-21"
        iyy="3.7978E-05"
        iyz="1.0686E-23"
        izz="3.5918E-05" />
    </inertial>
    <visual>
      <origin
        xyz="0 0 0"
        rpy="0 0 0" />
      <geometry>
        <mesh
          filename="package://garbage_quick_sort_robot/meshes/link_4.STL" />
      </geometry>
      <material
        name="">
        <color
          rgba="0.75294 0.75294 0.75294 1" />
      </material>
    </visual>
    <collision>
      <origin
        xyz="0 0 0"
        rpy="0 0 0" />
      <geometry>
        <mesh
          filename="package://garbage_quick_sort_robot/meshes/link_4.STL" />
      </geometry>
    </collision>
  </link>
  <joint
    name="joint_4"
    type="continuous">
    <origin
      xyz="0.186 0 0"
      rpy="0 0 0" />
    <parent
      link="link_3" />
    <child
      link="link_4" />
    <axis
      xyz="0 -1 0" />
  </joint>
</robot>